Workbook

Sheet 테스트케이스
A1: ID | B1: 출처 | C1: 영역 | D1: 유형 | E1: 시나리오 | F1: 사전조건(정책) | G1: 테스트 절차 | H1: 기대결과 | I1: 실제 결과 | J1: 실행결과 | K1: 실행일 | L1: 결함 ID | M1: 리뷰 메모 | N1: 우선순위 | O1: AI 원문 절차(수정 전) | P1: 버전 | Q1: 1.1 회귀 결과 | R1: 1.1 회귀 메모
A2: TC-01 | B2: AI수정 | C2: UI | D2: 정상 | E2: 서울 호텔 검색 | F2: 초기화 | G2: 1. 홈 접속 2. 도시: 서울 선택 3. 체크인 = 오늘+30일, 체크아웃 = 오늘+32일 (2박) 4. 인원 2명 5. 호텔 검색 클릭 | H2: 검색 결과에 서울 호텔 2개 노출 - 서울 그랜드 호텔: 1박 최저 120,000원, 예약 가능 객실 3개 - 두 번째 호텔: 1박 최저 95,000원, 예약 가능 객실 2개 | I2: 서울 호텔 2개 노출. 서울 그랜드 호텔 1박 최저 120,000원·예약 가능 객실 3개 / 한강 리버뷰 호텔 95,000원·2개 | J2: Pass | K2: 2026-10-10 | M2: 'D+30' 표기가 '최대 30박'으로 오해될 수 있음(리뷰 중 실제로 혼동). 실행자가 바로 이해할 수 있게 실제 날짜 또는 '오늘+n일'로 표기 권장 Playwright UI 자동화: tests/ui/search.spec.ts | N2: High | O2: ① index.html 접속 ② search-city=서울, checkin D+30, checkout D+32, guests 2 ③ search-submit 클릭 | P2: 1.0 | Q2: Pass | R2: 자동화 회귀 (10/10): 1.0과 동일
A3: TC-02 | B3: AI | C3: API | D3: 정상 | E3: 인원 조건 필터링 | F3: 초기화 | G3: GET /api/hotels?city=부산&checkIn=D+30&checkOut=D+32&guests=5 | H3: 200, 배열 길이 1, id=3, availableRooms=1, minPrice=450000. 호텔 4(최대 3인)는 미포함 | I3: 200, 호텔 3만 반환 (availableRooms=1, minPrice=450000) | J3: Pass | K3: 2026-10-10 | M3: Playwright API 자동화: tests/api/hotels.spec.ts | N3: High | P3: 1.0 | Q3: Pass | R3: 자동화 회귀 (10/10): 1.0과 동일
A4: TC-03 | B4: AI | C4: API | D4: 경계 | E4: guests 최솟값/최댓값 허용 | F4: 초기화 | G4: guests=1, guests=10으로 각각 GET /api/hotels (서울, D+30~D+32) | H4: guests=1: 200, 호텔 1·2 반환. guests=10: 200, [] (수용 가능한 객실 없음). 두 경우 모두 400 아님 | I4: guests=1: 200, 호텔 1·2 반환 / guests=10: 200, [] | J4: Pass | K4: 2026-10-10 | M4: Playwright API 자동화: tests/api/hotels.spec.ts | N4: Mid | P4: 1.0 | Q4: Pass | R4: 자동화 회귀 (10/10): 1.0과 동일
A5: TC-04 | B5: AI수정 | C5: API | D5: 경계/예외 | E5: guests 범위·형식 위반 | F5: 초기화 | G5: guests=0, 11, 2.5, abc로 각각 GET /api/hotels | H5: 4건 모두 400, error.code=VALIDATION_ERROR, error.details.guests 존재 | I5: 4건 모두 400, error.code=VALIDATION_ERROR | J5: Pass | K5: 2026-10-10 | M5: AI가 명세에 없는 error.details 키를 기대결과로 넘겨짚음 → 조건 제외. README에는 details 포함 조건이 정의되어 있지 않음(필드 입력 오류 예시만 있음). 자동화 1차 실행(10/10)에서 details 조건으로 Fail 후 리뷰하여 TC 수정 Playwright API 자동화: tests/api/hotels.spec.ts [1.1] 명세에 'VALIDATION_ERROR는 항상 details 포함'이 추가되어 details 조건 복구. 결과적으로 AI 원문 기대결과가 1.1 명세와 일치함. (1.0 기대결과: 4건 모두 400, error.code=VALIDATION_ERROR) | N5: High | O5: [기대결과 원문] 4건 모두 400, error.code=VALIDATION_ERROR, error.details에 guests 키 존재 | P5: 1.0 | Q5: Pass | R5: 자동화 회귀 (10/10): 1.0과 동일 / details 검증 복구 후 재실행 Pass
A6: TC-05 | B6: AI수정 | C6: UI | D6: 경계 | E6: 체크인=오늘 허용, 어제 거부 | F6: 체크인은 오늘부터 가능 (정책) | G6: ① 부산 / 체크인 오늘(10/8) ~ 체크아웃 10/9 / 2명 검색 ② 부산 / 체크인 10/6(과거) ~ 10/10 / 2명 검색 | H6: ① 검색 결과 노출 ② '체크인 날짜는 오늘 이후여야 합니다.' 에러 표시 | I6: ① 호텔 2개 노출 (로그 GET /api/hotels status=200) ② 에러 메시지 표시 | J6: Pass | K6: 2026-10-08 | M6: API로 분류됐으나 UI로 재현 가능. 에러 문구 '오늘 이후'는 오늘 포함 여부가 모호함(실제로는 오늘 허용) → 문구 개선 제안 | N6: High | O6: ① checkIn=D, checkOut=D+1 ② checkIn=D-1, checkOut=D+1 (서울, 2명) | P6: 1.0 | Q6: 미실행 | R6: 1.1에서 다시 실행하지 않음
A7: TC-06 | B7: AI수정 | C7: UI | D7: 경계 | E7: 체크아웃=체크인(0박) | F7: 체크아웃은 체크인 다음 날 이후 (정책) | G7: 1. 서울 / 체크인 12/31 ~ 체크아웃 12/31 / 2명 2. 호텔 검색 클릭 | H7: '체크아웃 날짜는 체크인 날짜보다 이후여야 합니다.' 에러 표시, 검색 진행 안 됨 | I7: 에러 메시지 표시. 서버 로그 없음(화면에서 차단) | J7: Pass | K7: 2026-10-07 | M7: 화면에서만 차단되고 서버까지 요청이 가지 않음 → 서버 측 검증은 API 단계에서 별도 확인 필요 | N7: High | O7: GET /api/hotels?city=서울&checkIn=D+30&checkOut=D+30&guests=2 | P7: 1.0 | Q7: 미실행 | R7: 1.1에서 다시 실행하지 않음
A8: TC-07 | B8: AI수정 | C8: UI | D8: 경계 | E8: 최대 30박 | F8: 최대 30박까지 예약 가능 (정책) | G8: 1. 서울 / 체크인 2026-12-31 ~ 체크아웃 2027-01-31 (31박) / 2명 2. 호텔 검색 클릭 | H8: '최대 30박까지 예약할 수 있습니다.' 에러 표시 | I8: 검색 결과 화면에서 에러 표시. 로그 [ERROR] GET /api/hotels status=400 VALIDATION_ERROR | J8: Pass | K8: 2026-10-07 | M8: 31박 차단만 확인, 30박 허용 케이스는 미실행. 0박(TC-06)은 화면에서, 31박은 서버에서 차단되어 검증 위치가 일관되지 않음 | N8: High | O8: ① checkIn=D+10, checkOut=D+40(30박) ② checkOut=D+41(31박) | P8: 1.0 | Q8: 미실행 | R8: 1.1에서 다시 실행하지 않음
A9: TC-08 | B9: AI수정 | C9: API | D9: 예외 | E9: 날짜 형식 오류·존재하지 않는 날짜 | F9: 초기화 | G9: checkIn을 2027/03/10, 2027-02-29(평년), 2027-13-01로 각각 요청 | H9: 3건 모두 400 VALIDATION_ERROR, error.details.checkIn 존재 | I9: 3건 모두 400, error.code=VALIDATION_ERROR | J9: Pass | K9: 2026-10-10 | M9: AI가 명세에 없는 error.details 키를 기대결과로 넘겨짚음 → 조건 제외. README에는 details 포함 조건이 정의되어 있지 않음(필드 입력 오류 예시만 있음). 자동화 1차 실행(10/10)에서 details 조건으로 Fail 후 리뷰하여 TC 수정 날짜는 실행일 기준으로 계산 (평년 2/29는 다가오는 평년으로 생성) Playwright API 자동화: tests/api/hotels.spec.ts [1.1] 명세에 'VALIDATION_ERROR는 항상 details 포함'이 추가되어 details 조건 복구. 결과적으로 AI 원문 기대결과가 1.1 명세와 일치함. (1.0 기대결과: 3건 모두 400 VALIDATION_ERROR) | N9: Mid | O9: [기대결과 원문] 3건 모두 400 VALIDATION_ERROR, details에 checkIn 키 존재 | P9: 1.0 | Q9: Pass | R9: 자동화 회귀 (10/10): 1.0과 동일 / details 검증 복구 후 재실행 Pass
A10: TC-09 | B10: AI수정 | C10: API | D10: 예외 | E10: 필수 파라미터 누락 | F10: 초기화 | G10: city 없이 GET /api/hotels?checkIn=D+30&checkOut=D+32&guests=2 | H10: 400 VALIDATION_ERROR, error.details.city 존재. logs/app.log에 [ERROR] GET /api/hotels user=- params={city 없음} ... status=400 1줄 기록 | I10: 400 VALIDATION_ERROR. app.log에 [ERROR] GET /api/hotels ... status=400 1줄 기록 확인 | J10: Pass | K10: 2026-10-10 | M10: AI가 명세에 없는 error.details 키를 기대결과로 넘겨짚음 → 조건 제외. README에는 details 포함 조건이 정의되어 있지 않음(필드 입력 오류 예시만 있음). 자동화 1차 실행(10/10)에서 details 조건으로 Fail 후 리뷰하여 TC 수정 Playwright API 자동화: tests/api/hotels.spec.ts [1.1] 명세에 'VALIDATION_ERROR는 항상 details 포함'이 추가되어 details 조건 복구. 로그 형식에 user= 항목도 추가되어 반영. 결과적으로 AI 원문 기대결과가 1.1 명세와 일치함. (1.0 기대결과: 400 VALIDATION_ERROR. logs/app.log에 [ERROR] GET /api/hotels ... status=400 1줄 기록) | N10: Mid | O10: [기대결과 원문] 400 VALIDATION_ERROR, details에 city 키 존재. logs/app.log에 [ERROR] GET /api/hotels ... status=400 1줄 기록 | P10: 1.0 | Q10: Pass | R10: 1차 Fail → 분류 A (명세 변경): 로그 형식에 user= 추가, details 추가로 테스트 조건 불일치. 앱 동작은 정상 2차 (10/10): 테스트를 1.1 기준(details.city, user= 로그 형식)으로 수정 후 Pass
A11: TC-10 | B11: AI | C11: API | D11: 정상 | E11: 만실 호텔은 검색에서 제외 | F11: 초기화 후 객실 4, 5에 D+30~D+32 예약 생성 | G11: GET /api/hotels?city=서울&checkIn=D+30&checkOut=D+32&guests=2 | H11: 200, 배열 길이 1, id=1만 포함(호텔 2 제외), availableRooms=3 | I11: 200, 호텔 1만 반환 (availableRooms=3), 호텔 2 제외 | J11: Pass | K11: 2026-10-10 | M11: UI TC-01과 데이터가 겹치지 않도록 오늘+40~42일로 실행 Playwright API 자동화: tests/api/hotels.spec.ts | N11: High | P11: 1.0 | Q11: Pass | R11: 자동화 회귀 (10/10): 1.0과 동일
A12: TC-11 | B12: AI수정 | C12: UI | D12: 정상 | E12: 객실 목록과 기간 총액 표시 | F12: 초기화 | G12: hotel.html?id=1&checkIn=D+30&checkOut=D+32&guests=2 접속 | H12: 호텔 상세에 다음 항목 정상 노출: 호텔명, 주소, 별점, 설명, 숙박 요약(n박·n명·체크인~체크아웃), 객실별 1박 요금·기간 총액·최대 인원·예약 가능 여부 (서울 그랜드 호텔 2박 기준 객실 총액 240,000 / 320,000 / 560,000원) | I12: 호텔명·주소·별점(★ 4.6)·설명·숙박 요약(2박·2명) 노출. 객실 3개 1박 요금·기간 총액(240,000 / 320,000 / 560,000원)·최대 인원·예약 가능 표시 | J12: Pass | K12: 2026-10-10 | M12: AI 원문은 data-testid 값만 나열 → 사용자가 실제로 보는 화면 요소 기준으로 검증 항목 보강 Playwright UI 자동화: tests/ui/hotel-detail.spec.ts | N12: High | P12: 1.0 | Q12: Pass | R12: 자동화 회귀 (10/10): 1.0과 동일
A13: TC-12 | B13: AI | C13: API | D13: 예외 | E13: 객실 조회 시 잘못된 호텔 id | F13: 초기화 | G13: ① GET /api/hotels/999/rooms ② GET /api/hotels/abc/rooms | H13: ①: 404 NOT_FOUND. ②: 400 VALIDATION_ERROR | I13: ①: 404 NOT_FOUND / ②: 400 VALIDATION_ERROR | J13: Pass | K13: 2026-10-10 | M13: Playwright API 자동화: tests/api/hotels.spec.ts | N13: Mid | P13: 1.0 | Q13: Pass | R13: 자동화 회귀 (10/10): 1.0과 동일
A14: TC-13 | B14: AI | C14: API | D14: 정상 | E14: 기존 예약 반영한 available 계산 | F14: R1 생성 | G14: GET /api/hotels/1/rooms?checkIn=D+31&checkOut=D+33&guests=2 | H14: 200. room id 1은 available:false, id 2·3은 available:true | I14: 200. room 1 available:false, room 2·3 available:true | J14: Pass | K14: 2026-10-10 | M14: R1을 오늘+50~52일로 생성 후 오늘+51~53일 조회 (데이터 격리) Playwright API 자동화: tests/api/hotels.spec.ts | N14: High | P14: 1.0 | Q14: Pass | R14: 자동화 회귀 (10/10): 1.0과 동일
A15: TC-14 | B15: AI수정 | C15: UI | D15: 정상 | E15: 검색부터 예약 완료까지 E2E | F15: 총 결제 금액 = 1박 요금 × 숙박일수 (정책) | G15: 1. 제주 / 10/8 ~ 10/11 (3박) / 2명 검색 2. 제주 포레스트 리조트 → 가든 더블(1박 130,000원) 선택 3. 예약 정보 입력 화면의 총 결제 금액 확인 4. 테스트용 정보 입력 후 예약 확정 5. 로그 totalPrice 및 '내 예약 조회' 금액 확인 | H15: 입력 화면, 완료 화면, 조회 화면, 저장 금액 모두 390,000원 | I15: 입력 화면 390,000원 / 저장 금액 520,000원 (RSV-26FFE469, 로그 16:12:01) | J15: Fail | K15: 2026-10-08 | L15: #1 | M15: 원문 기대결과가 개발 관점(data-testid, DB 행 추가)이고 '예약 완료 여부' 위주라 금액 결함을 놓치기 쉬움 → 화면 금액과 저장 금액 대조로 재작성 | N15: High | O15: ① TC-01 검색 ② hotel-detail-btn-1 ③ room-select-btn-1 ④ 이름 홍길동, 이메일 hong@test.com, 전화 010-1234-5678 ⑤ booking-submit | P15: 1.0 | Q15: Fail | R15: 결함 #1 재현 (1.0과 같은 값: 조회 화면 520,000원)
A16: TC-15 | B16: AI | C16: API | D16: 정상 | E16: 예약 생성 응답 검증 | F16: 초기화 | G16: POST /api/reservations (객실 2, D+30~D+33, 3명, 유효 정보) | H16: 201. status=CONFIRMED, nights=3, totalPrice=480000, room.pricePerNight=160000, cancelledAt=null. id 정규식 ^RSV-.{8}$ 일치 | I16: 201. status·nights·room.pricePerNight·cancelledAt·id 형식은 기대대로이나 totalPrice=640000 (기대 480000) | J16: Fail | K16: 2026-10-10 | L16: #1 | M16: '객실 2'가 객실 ID 2번인지 객실 2개 예약인지 모호(2실 예약 기능은 없음). 객실 ID로 명시 필요 결함 #1과 같은 원인으로 API에서도 재현 (test.fail로 표시) Playwright API 자동화: tests/api/reservations.spec.ts | N16: High | P16: 1.0 | Q16: Fail | R16: 결함 #1 재현 (1.0과 같은 값: totalPrice 640000)
A17: TC-16 | B17: AI | C17: API | D17: 경계 | E17: 객실 수용 인원 초과 | F17: 초기화 | G17: POST 객실 1(정원 2), guests=3 / 같은 조건 guests=2 | H17: guests=3: 400 VALIDATION_ERROR, DB 행 증가 없음. guests=2: 201 | I17: guests=3: 400 VALIDATION_ERROR, DB 행 증가 없음 / guests=2: 201 | J17: Pass | K17: 2026-10-10 | M17: TC-15와 같은 표기 문제. UI에서는 3명 검색 시 정원 2명 객실이 '예약 불가'로 표시됨을 확인(10/7). 서버 차단 여부는 API 단계에서 확인 → 서버 차단 확인 (10/10) Playwright API 자동화: tests/api/reservations.spec.ts | N17: High | P17: 1.0 | Q17: Pass | R17: 자동화 회귀 (10/10): 1.0과 동일
A18: TC-17 | B18: AI수정 | C18: UI | D18: 예외 | E18: 기간 겹치는 중복 예약 | F18: 같은 객실은 기간이 겹치면 예약 불가 (정책) 서울 그랜드 호텔 스탠다드 더블에 11/1~11/3 예약 존재 (RSV-A375CEDF) | G18: 1. 서울 / 11/2 ~ 11/4 / 2명 검색 2. 서울 그랜드 호텔 → 객실 목록 확인 | H18: 스탠다드 더블 '예약 불가' 표시 | I18: 스탠다드 더블 '예약 불가' 표시 | J18: Pass | K18: 2026-10-08 | M18: 기간 겹침 4가지 유형(뒤쪽/앞쪽/감쌈/포함) 중 뒤쪽 1가지만 다룸 → TC-32, 37, 38 추가. 화면 표시만 확인했으며 서버 차단은 API 단계에서 확인 → 서버 차단 확인 (10/10): URL 직접 진입으로 제출해도 409 ROOM_UNAVAILABLE, 예약 생성 안 됨. 4가지 겹침 유형 비교에 사용 (TC-37 메모 참고) Playwright UI 자동화: tests/ui/overlap.spec.ts | N18: High | O18: POST 객실 1, D+31~D+33 | P18: 1.0 | Q18: Pass | R18: 자동화 회귀 (10/10): 1.0과 동일
A19: TC-18 | B19: AI | C19: API | D19: 경계 | E19: 체크아웃일=다음 체크인일 허용 | F19: R1 생성 | G19: POST 객실 1, D+32~D+34 | H19: 201, status=CONFIRMED. DB에 room_id=1 CONFIRMED 2건 | I19: 201 CONFIRMED. DB에 room_id=1 CONFIRMED 2건 확인 | J19: Pass | K19: 2026-10-10 | M19: R1을 오늘+70~72일로 생성 (데이터 격리) Playwright API 자동화: tests/api/reservations.spec.ts | N19: High | P19: 1.0 | Q19: Pass | R19: 자동화 회귀 (10/10): 1.0과 동일
A20: TC-19 | B20: AI | C20: API | D20: 정상 | E20: 취소된 예약 기간 재예약 | F20: R1 생성 후 취소 | G20: POST 객실 1, D+30~D+32 (다른 이메일) | H20: 201. DB에 room_id=1 행 2건(CANCELLED 1, CONFIRMED 1) | I20: 201. DB 해당 기간 room_id=1 행 2건 (CANCELLED 1, CONFIRMED 1) | J20: Pass | K20: 2026-10-10 | M20: R1을 오늘+76~78일로 생성 (데이터 격리) Playwright API 자동화: tests/api/reservations.spec.ts | N20: Mid | P20: 1.0 | Q20: Pass | R20: 자동화 회귀 (10/10): 1.0과 동일
A21: TC-20 | B21: AI | C21: API | D21: 예외 | E21: 존재하지 않는 객실 | F21: 초기화 | G21: POST /api/reservations roomId=999, 나머지 유효 | H21: 404 NOT_FOUND, DB 행 증가 없음 | I21: 404 NOT_FOUND, DB 행 증가 없음 | J21: Pass | K21: 2026-10-10 | M21: Playwright API 자동화: tests/api/reservations.spec.ts | N21: Mid | P21: 1.0 | Q21: Pass | R21: 자동화 회귀 (10/10): 1.0과 동일
A22: TC-21 | B22: AI | C22: API | D22: 예외 | E22: JSON 아닌 본문 | F22: 초기화 | G22: POST /api/reservations, Content-Type: application/json, 본문 {roomId:1, | H22: 400 INVALID_JSON, 응답이 {error:{code,message}} 구조. 500 아님 | I22: 400 INVALID_JSON, 응답이 {error:{code,message}} 구조 | J22: Pass | K22: 2026-10-10 | M22: Playwright API 자동화: tests/api/reservations.spec.ts | N22: Mid | P22: 1.0 | Q22: Pass | R22: 자동화 회귀 (10/10): 1.0과 동일
A23: TC-22 | B23: AI | C23: API | D23: 경계 | E23: 이름 길이 1/50/51자, 빈 값 | F23: 초기화 | G23: 이름만 바꿔 4회 POST (날짜는 매번 다른 기간) | H23: 1자·50자: 201. 51자·빈 문자열: 400 VALIDATION_ERROR, details.name 존재 | I23: 1자·50자: 201 / 51자·빈 문자열: 400 VALIDATION_ERROR, details.name 존재 | J23: Pass | K23: 2026-10-10 | M23: Playwright API 자동화: tests/api/reservations.spec.ts | N23: Mid | P23: 1.0 | Q23: Pass | R23: 자동화 회귀 (10/10): 1.0과 동일
A24: TC-23 | B24: AI | C24: API | D24: 경계 | E24: 전화번호·이메일 형식 | F24: 초기화 | G24: phone=01012345678, 010-123-4567, 010 1234 5678 / email=hong@, hong.test.com으로 각각 POST | H24: 01012345678: 201. 나머지 4건: 400 VALIDATION_ERROR, details에 해당 필드(phone/email) 키 존재 | I24: 01012345678: 201 / 010-123-4567: 201 (예약 생성됨, 기대 400) / 010 1234 5678, hong@, hong.test.com: 400, details에 해당 필드 존재 | J24: Fail | K24: 2026-10-10 | L24: #5 | M24: 가운데 3자리 번호가 명세 형식(010-1234-5678)과 다르지만 허용됨 → 결함 #5 등록 (test.fail로 표시) Playwright API 자동화: tests/api/reservations.spec.ts | N24: Mid | P24: 1.0 | Q24: Fail | R24: 결함 #5 재현 (자동화 + 탐색 테스트): 010-123-4567 예약됨
A25: TC-24 | B25: AI | C25: UI | D25: 예외 | E25: 예약 입력 폼 검증 메시지 | F25: 초기화, book.html(객실 1, D+30~D+32, 2명) 진입 | G25: 이름 공란, 이메일 abc, 전화 123 입력 후 booking-submit | H25: guest-name-error, guest-email-error, guest-phone-error 3개 모두 표시. complete.html로 이동하지 않음. DB 예약 0건 유지 | I25: 이름·이메일·전화번호 오류 메시지 3개 동시 표시. book.html에 머무름, 예약 생성 요청(POST /api/reservations) 미발생 | J25: Pass | K25: 2026-10-10 | M25: 전화번호 단독 오류는 확인(10/7, '예: 010-1234-5678' 형식 안내 포함). 3개 필드 동시 오류는 미실행 → 3개 필드 동시 오류 확인 (10/10). DB 대신 예약 생성 요청이 서버로 나가지 않는 것으로 확인 Playwright UI 자동화: tests/ui/booking.spec.ts | N25: High | P25: 1.0 | Q25: Pass | R25: 자동화 회귀 (10/10): 1.0과 동일
A26: TC-25 | B26: AI수정 | C26: UI | D26: 정상 | E26: 대소문자 다른 이메일로 조회 | F26: 예약 RSV-199A1DB7 존재 (이메일 guest.test@example.com) | G26: 1. 내 예약 조회 2. 예약번호 RSV-199A1DB7 + 이메일 GUEST.TEST@example.com(대문자) 입력 후 조회 | H26: 예약 상세 정상 표시, 상태 '예약 확정' | I26: 예약 상세 표시 (로그 status=200). 참고: 'SOPHIA'만 입력 시 404 | J26: Pass | K26: 2026-10-07 | M26: 'R1' 같은 내부 약어 대신 실제 예약번호로 기재 | N26: High | O26: my.html에서 lookup-id=R1 번호, lookup-email=HONG@TEST.COM → lookup-submit | P26: 1.0 | Q26: 미실행 | R26: 1.1에서 다시 실행하지 않음
A27: TC-26 | B27: AI | C27: API | D27: 예외 | E27: 조회 시 이메일 불일치·누락 | F27: R1 생성 | G27: ① GET /api/reservations/{R1}?email=other@test.com ② GET /api/reservations/{R1} ③ GET /api/reservations/RSV-00000000?email=hong@test.com | H27: ①: 404 NOT_FOUND. ②: 400 VALIDATION_ERROR. ③: 404 NOT_FOUND. ①의 응답 본문에 예약 정보(이름·전화) 미포함 | I27: ①: 404 NOT_FOUND, 응답에 이름·전화 미포함 / ②: 400 VALIDATION_ERROR / ③: 404 NOT_FOUND | J27: Pass | K27: 2026-10-10 | M27: R1을 오늘+100~102일로 생성 (데이터 격리) Playwright API 자동화: tests/api/reservations.spec.ts | N27: High | P27: 1.0 | Q27: Pass | R27: 자동화 회귀 (10/10): 1.0과 동일
A28: TC-27 | B28: AI | C28: UI | D28: 정상 | E28: 예약 취소 확정 | F28: R1 생성, my.html에서 R1 조회 완료 | G28: cancel-btn → cancel-confirm 패널 노출 확인 → cancel-confirm-yes | H28: cancel-result 표시. reservation-status 텍스트 "취소됨", data-status=CANCELLED. reservation-cancelled-at 값 표시. DB status=CANCELLED, cancelled_at NOT NULL | I28: 취소 후 상태 '취소됨', 로그 status=CANCELLED (RSV-199A1DB7) | J28: Pass | K28: 2026-10-07 | N28: High | P28: 1.0 | Q28: 미실행 | R28: 1.1에서 다시 실행하지 않음
A29: TC-28 | B29: AI수정 | C29: UI | D29: 정상 | E29: 취소 확인 패널에서 철회 | F29: R1 생성, my.html에서 R1 조회 완료 | G29: 1. 내 예약 조회 → 예약 상세 진입 2. 예약 취소 클릭 → 확인 패널 노출 확인 3. '아니요' 클릭 | H29: 확인 패널 닫힘, 상태 '예약 확정' 유지, 취소 요청(로그 /cancel) 없음 | I29: 패널 닫힘, 예약 확정 유지, 로그에 /cancel 없음 | J29: Pass | K29: 2026-10-08 | M29: 리뷰 초안에 TC-27(실제 취소) 확인 항목이 섞여 있어 '철회'만 확인하도록 분리. 확인 UI는 브라우저 팝업이 아닌 페이지 내 패널 | N29: Mid | O29: cancel-btn → cancel-confirm-no | P29: 1.0 | Q29: 미실행 | R29: 1.1에서 다시 실행하지 않음
A30: TC-29 | B30: AI | C30: API | D30: 예외 | E30: 이미 취소된 예약 재취소 | F30: R1 생성 후 취소(cancelled_at 값 기록) | G30: POST /api/reservations/{R1}/cancel {"email":"hong@test.com"} | H30: 409 ALREADY_CANCELLED. DB cancelled_at이 첫 취소 시각과 동일(갱신 안 됨) | I30: 409 ALREADY_CANCELLED. DB cancelled_at이 첫 취소 시각과 동일 | J30: Pass | K30: 2026-10-10 | M30: R1을 오늘+104~106일로 생성 (데이터 격리) Playwright API 자동화: tests/api/reservations.spec.ts | N30: Mid | P30: 1.0 | Q30: Pass | R30: 자동화 회귀 (10/10): 1.0과 동일
A31: TC-30 | B31: AI수정 | C31: UI | D31: 경계 | E31: 체크인 당일 취소 불가, 전날 가능 | F31: 체크인 당일부터는 취소 불가 (정책) | G31: 1. 제주 / 오늘(10/8) ~ 10/11 예약 생성 (RSV-26FFE469) 2. 내 예약 조회 → 예약 취소 → '예' | H31: '체크인 당일 이후에는 예약을 취소할 수 없습니다.' 표시, 상태 '예약 확정' 유지 | I31: 에러 메시지 표시, 상태 유지. 로그 status=409 CANCELLATION_CLOSED (체크인 전 예약 취소 허용은 RSV-199A1DB7로 확인) | J31: Pass | K31: 2026-10-08 | M31: 원문은 API 전용 절차 → 화면으로 재현. 핵심은 '취소 성공'이 아니라 '당일 취소 차단'임을 절차에 명확히 표기 | N31: High | O31: A, B 각각 POST /cancel (올바른 이메일) | P31: 1.0 | Q31: 미실행 | R31: 1.1에서 다시 실행하지 않음
A32: TC-31 | B32: QA추가 | C32: UI | D32: 정상 | E32: 예약~조회 화면 간 금액 일치 | F32: 총 결제 금액은 모든 화면에서 동일해야 함 | G32: 1. TC-14와 동일하게 예약 생성 2. 예약 정보 입력 / 예약 완료 / 내 예약 조회 화면의 총 결제 금액 비교 | H32: 모든 화면 390,000원 | I32: 예약 정보 입력 390,000원 / 조회 화면 520,000원 (RSV-26FFE469) | J32: Fail | K32: 2026-10-08 | L32: #1 | M32: AI 생성 TC에 없던 화면 간 정합성 관점. 고객이 예약 때와 다른 금액을 보게 됨 | N32: High | P32: 1.0 | Q32: Fail | R32: 결함 #1 재현 (탐색 테스트)
A33: TC-32 | B33: QA추가 | C33: UI | D33: 예외 | E33: 기존 예약 앞쪽에 걸치는 기간 예약 (UI 우회) | F33: 같은 객실은 기간이 겹치면 예약 불가 (정책) 객실 1에 11/1~11/3 예약 존재 | G33: 1. 주소창에 직접 입력하여 예약 화면 진입 localhost:3000/book.html?hotelId=1&roomId=1&checkIn=2026-10-31&checkOut=2026-11-02&guests=2 2. 정보 입력 후 예약 확정 | H33: 409 에러, 예약 생성 안 됨 | I33: 201 성공, RSV-E71EEA68 생성 → 11/1 숙박일 이중 예약 (로그 16:21:46) | J33: Fail | K33: 2026-10-08 | L33: #2 | M33: 객실 목록 화면은 '예약 불가'로 정상 표시 → 화면만 검증했다면 놓쳤을 결함. URL 조작으로 서버 검증 확인 Playwright UI 자동화로 재확인 (10/10, test.fail): tests/ui/overlap.spec.ts | N33: High | P33: 1.0 | Q33: Fail | R33: 결함 #2 재현 (201 중복 예약)
A34: TC-33 | B34: QA추가 | C34: UI | D34: 예외 | E34: 해외 전화번호 입력 | F34: 전화번호 입력 정책 미정의 (이름은 영문 허용) | G34: 1. 예약 정보 입력 화면 진입 2. 이름 'Jane Doe', 전화번호 07700900123(영국) 입력 후 예약 확정 | H34: 정책 확인 필요 | I34: '전화번호 형식이 올바르지 않습니다.' 표시, 예약 불가 | J34: 확인필요 | K34: 2026-10-07 | L34: #4 | M34: 이름(영문 허용)과 전화번호(국내 형식만) 정책 불일치. 여행 서비스 특성상 해외 사용자 고려 필요 [QA 정책 제안 2026-10-13, 확정 B] 국가 선택 + +국가번호(E.164) 형식으로 국제 전화번호 허용. 선택지: A 국내 형식만 유지(안내 문구 추가) / B 국제 형식 허용 / C 전화번호 선택 입력. 이유: 숙박 서비스는 해외 고객 전제, 영문 이름 허용과 일관. 한 형식으로 저장하면 PHONE_RE가 011·016 앞자리와 하이픈 혼용까지 허용하는 문제(#5)도 국가별 규칙으로 재정의 가능. 연락처는 숙소 운영에 필요해 C보다 나음 | N34: Mid | P34: 1.0 | Q34: 미실행 | R34: 1.1에서 다시 실행하지 않음
A35: TC-34 | B35: QA추가 | C35: 로그 | D35: 예외 | E35: 로그 내 개인정보 마스킹 | F35: 개인정보는 마스킹하여 기록 | G35: 1. 예약 생성 / 조회 / 취소 수행 2. logs/app.log 확인 | H35: 이름·이메일·전화번호 마스킹 기록 | I35: 이름·이메일·전화번호 평문 기록 | J35: Fail | K35: 2026-10-07 | L35: #3 | M35: 기능 테스트만으로는 드러나지 않는 비기능 결함 | N35: Mid | P35: 1.0 | Q35: Fail | R35: 결함 #3 재현 (탐색 테스트): 로그에 이름·이메일·전화번호 평문
A36: TC-35 | B36: QA추가 | C36: UI | D36: 예외 | E36: 예약 확정 버튼 더블 클릭 | F36: 1회 클릭 = 1건 예약 | G36: 1. 예약 정보 입력 2. 예약 확정 버튼 빠르게 2회 클릭 3. 로그 POST /api/reservations 건수 확인 | H36: 예약 1건만 생성 | I36: 더블 클릭 시 POST /api/reservations 1건, 201 (RSV-41FB08EE). 추가 예약 없음 | J36: Pass | K36: 2026-10-10 | M36: 실무 빈출 결함 유형. AI 미생성 수동 실행 (10/10) | N36: High | P36: 1.0 | Q36: 미실행 | R36: 1.1에서 다시 실행하지 않음
A37: TC-36 | B37: QA추가 | C37: UI | D37: 예외 | E37: 예약 완료 후 뒤로 가기 / 새로고침 | F37: 완료 후 재제출 없음 | G37: 1. 예약 완료 화면 진입 2. 새로고침 / 뒤로 가기 후 다시 앞으로 | H37: 추가 예약 생성 안 됨 | I37: 뒤로 가기·새로고침 후 재제출 2회 모두 409 ROOM_UNAVAILABLE, 추가 예약 없음 (RSV-41FB08EE 1건 유지) | J37: Pass | K37: 2026-10-10 | L37: #6 | M37: AI 미생성 수동 실행 (10/10). 서버 중복 방지는 정상이나 화면 문제 관찰 → 개선 제안 #6 ① 예약 완료 후 뒤로 가기 시 버튼이 '예약 처리 중...'에 멈춰 있음 ② 새로고침 시 입력 폼이 다시 활성화되고, 제출하면 '이미 예약된 객실입니다' 에러 표시 → 방금 예약한 사용자가 예약 실패로 오해할 수 있음 | N37: Mid | P37: 1.0 | Q37: 미실행 | R37: 1.1에서 다시 실행하지 않음
A38: TC-37 | B38: QA추가 | C38: UI | D38: 예외 | E38: 기존 예약을 감싸는 기간 예약 (UI 우회) | F38: 객실 1에 11/1~11/3 예약 존재 | G38: TC-32와 동일 방식으로 10/31 ~ 11/4 예약 시도 | H38: 409 에러, 예약 생성 안 됨 | I38: 201 성공, 예약 생성됨 → 기존 예약 기간 전체가 이중 예약 (기대 409) → 결함 #2와 같은 패턴 (test.fail로 표시) | J38: Fail | K38: 2026-10-10 | L38: #2 | M38: 4가지 겹침 유형(TC-17 뒤쪽 / 32 앞쪽 / 37 감싸기 / 38 포함)을 비교해 공통 원인 패턴을 찾음: 체크인이 기존 예약보다 앞이면 허용(32·37), 기존 예약 안이면 차단(17·38) → 결함 #2로 통합, 이슈 제목 변경 기간 겹침 유형 보완 (TC-17 리뷰 결과) Playwright UI 자동화: tests/ui/overlap.spec.ts (기존 예약은 API로 생성, 날짜는 오늘+n일로 계산) | N38: High | P38: 1.0 | Q38: Fail | R38: 결함 #2 재현 (201 중복 예약)
A39: TC-38 | B39: QA추가 | C39: UI | D39: 예외 | E39: 기존 예약 안에 포함되는 기간 예약 (UI 우회) | F39: 객실 1에 11/1~11/3 예약 존재 | G39: TC-32와 동일 방식으로 11/1 ~ 11/2 예약 시도 | H39: 409 에러, 예약 생성 안 됨 | I39: 409 ROOM_UNAVAILABLE, "선택한 날짜에 이미 예약된 객실입니다." 표시, 예약 생성 안 됨 | J39: Pass | K39: 2026-10-10 | M39: 기간 겹침 유형 보완 (TC-17 리뷰 결과) Playwright UI 자동화: tests/ui/overlap.spec.ts (기존 예약은 API로 생성, 날짜는 오늘+n일로 계산) | N39: High | P39: 1.0 | Q39: Pass | R39: 자동화 회귀 (10/10): 1.0과 동일
A40: TC-39 | B40: AI | C40: UI | D40: 정상 | E40: 이메일 회원가입 후 자동 로그인 | F40: 초기화, 비로그인 | G40: 1. 헤더 로그인 → 회원가입 2. 이름·이메일·비밀번호(영문+숫자 8자 이상)·비밀번호 확인 입력 후 가입 | H40: 가입 후 원래 화면으로 복귀, 헤더에 이름 표시. DB users에 provider=EMAIL 행 생성 | I40: 가입 후 /index.html 복귀, 헤더 "가입테스트님", DB provider=EMAIL | J40: Pass | K40: 2026-10-10 | L40: #13 | M40: 근거: 명세 「회원가입 → returnTo 화면으로 복귀」, 「201 + sid 쿠키 (가입 즉시 로그인)」, users 테이블 Playwright UI 자동화: tests/ui/auth.spec.ts 2026-10-13 수동 확인: 가입 성공 후 안내 없이 returnTo로 이동, 로그인 신호가 헤더 이름뿐 → 개선 제안 #13 (가입 완료 안내 토스트) | N40: High | P40: 1.1
...

Sheet AI 리뷰 요약
A1: AI 생성 TC 리뷰 요약
A2: 숫자는 '테스트케이스' 시트에서 자동 집계됩니다. v1.0·v1.1을 따로 집계합니다 (v1.0: 2~39행, v1.1: 40~81행).
A3: 출처별
A4: v1.0 (TC-01~38)
A5: 출처 | B5: 건수 | C5: Pass | D5: Fail | E5: 확인필요 | F5: 미실행
A6: AI | B6: =COUNTIF(테스트케이스!$B$2:$B$39,A6) | C6: =COUNTIFS(테스트케이스!$B$2:$B$39,A6,테스트케이스!$J$2:$J$39,"Pass") | D6: =COUNTIFS(테스트케이스!$B$2:$B$39,A6,테스트케이스!$J$2:$J$39,"Fail") | E6: =COUNTIFS(테스트케이스!$B$2:$B$39,A6,테스트케이스!$J$2:$J$39,"확인필요") | F6: =COUNTIFS(테스트케이스!$B$2:$B$39,A6,테스트케이스!$J$2:$J$39,"미실행")
A7: AI수정 | B7: =COUNTIF(테스트케이스!$B$2:$B$39,A7) | C7: =COUNTIFS(테스트케이스!$B$2:$B$39,A7,테스트케이스!$J$2:$J$39,"Pass") | D7: =COUNTIFS(테스트케이스!$B$2:$B$39,A7,테스트케이스!$J$2:$J$39,"Fail") | E7: =COUNTIFS(테스트케이스!$B$2:$B$39,A7,테스트케이스!$J$2:$J$39,"확인필요") | F7: =COUNTIFS(테스트케이스!$B$2:$B$39,A7,테스트케이스!$J$2:$J$39,"미실행")
A8: QA추가 | B8: =COUNTIF(테스트케이스!$B$2:$B$39,A8) | C8: =COUNTIFS(테스트케이스!$B$2:$B$39,A8,테스트케이스!$J$2:$J$39,"Pass") | D8: =COUNTIFS(테스트케이스!$B$2:$B$39,A8,테스트케이스!$J$2:$J$39,"Fail") | E8: =COUNTIFS(테스트케이스!$B$2:$B$39,A8,테스트케이스!$J$2:$J$39,"확인필요") | F8: =COUNTIFS(테스트케이스!$B$2:$B$39,A8,테스트케이스!$J$2:$J$39,"미실행")
A9: 합계 | B9: =SUM(B6:B8) | C9: =SUM(C6:C8) | D9: =SUM(D6:D8) | E9: =SUM(E6:E8) | F9: =SUM(F6:F8)
A11: v1.1 (TC-39~80)
A12: 출처 | B12: 건수 | C12: Pass | D12: Fail | E12: 확인필요 | F12: 미실행
A13: AI | B13: =COUNTIF(테스트케이스!$B$40:$B$81,A13) | C13: =COUNTIFS(테스트케이스!$B$40:$B$81,A13,테스트케이스!$J$40:$J$81,"Pass") | D13: =COUNTIFS(테스트케이스!$B$40:$B$81,A13,테스트케이스!$J$40:$J$81,"Fail") | E13: =COUNTIFS(테스트케이스!$B$40:$B$81,A13,테스트케이스!$J$40:$J$81,"확인필요") | F13: =COUNTIFS(테스트케이스!$B$40:$B$81,A13,테스트케이스!$J$40:$J$81,"미실행")
A14: AI수정 | B14: =COUNTIF(테스트케이스!$B$40:$B$81,A14) | C14: =COUNTIFS(테스트케이스!$B$40:$B$81,A14,테스트케이스!$J$40:$J$81,"Pass") | D14: =COUNTIFS(테스트케이스!$B$40:$B$81,A14,테스트케이스!$J$40:$J$81,"Fail") | E14: =COUNTIFS(테스트케이스!$B$40:$B$81,A14,테스트케이스!$J$40:$J$81,"확인필요") | F14: =COUNTIFS(테스트케이스!$B$40:$B$81,A14,테스트케이스!$J$40:$J$81,"미실행")
A15: QA추가 | B15: =COUNTIF(테스트케이스!$B$40:$B$81,A15) | C15: =COUNTIFS(테스트케이스!$B$40:$B$81,A15,테스트케이스!$J$40:$J$81,"Pass") | D15: =COUNTIFS(테스트케이스!$B$40:$B$81,A15,테스트케이스!$J$40:$J$81,"Fail") | E15: =COUNTIFS(테스트케이스!$B$40:$B$81,A15,테스트케이스!$J$40:$J$81,"확인필요") | F15: =COUNTIFS(테스트케이스!$B$40:$B$81,A15,테스트케이스!$J$40:$J$81,"미실행")
A16: 합계 | B16: =SUM(B13:B15) | C16: =SUM(C13:C15) | D16: =SUM(D13:D15) | E16: =SUM(E13:E15) | F16: =SUM(F13:F15)
A18: 핵심 지표
A19: 지표 | B19: v1.0 | C19: v1.1
A20: AI 생성 TC 수 | B20: =B6+B7 | C20: =B13+B14
A21: 그중 QA가 수정한 TC | B21: =B7 | C21: =B14
A22: QA가 추가한 TC | B22: =B8 | C22: =B15
A23: Fail 발생 TC 중 AI 원본 그대로인 TC | B23: =COUNTIFS(테스트케이스!$B$2:$B$39,"AI",테스트케이스!$J$2:$J$39,"Fail") | C23: =COUNTIFS(테스트케이스!$B$40:$B$81,"AI",테스트케이스!$J$40:$J$81,"Fail")
A24: Fail 발생 TC 중 AI수정·QA추가 TC | B24: =COUNTIFS(테스트케이스!$B$2:$B$39,"AI수정",테스트케이스!$J$2:$J$39,"Fail")+COUNTIFS(테스트케이스!$B$2:$B$39,"QA추가",테스트케이스!$J$2:$J$39,"Fail") | C24: =COUNTIFS(테스트케이스!$B$40:$B$81,"AI수정",테스트케이스!$J$40:$J$81,"Fail")+COUNTIFS(테스트케이스!$B$40:$B$81,"QA추가",테스트케이스!$J$40:$J$81,"Fail")
A26: 리뷰 결론
A27: v1.0
A28: 1. AI는 README(명세)를 그대로 따라가 API·개발자 관점 TC로 쏠림 (UI 7건 / API 23건). 사용자 시나리오는 사람이 보완해야 함
A29: 2. 내부 표기(D+30, 객실 2, R1, data-testid)가 많아 실무자가 바로 실행하기 어려움. 리뷰 과정에서 실제로 해석 혼동 발생
A30: 3. 기간 겹침 4가지 유형 중 1가지만 생성 → 누락된 '앞쪽 겹침'에서 중복 예약 결함(#2) 발견
A31: 4. AI TC는 명세에 적힌 입력 규칙·경계값 결함은 잡았지만(TC-23 → #5), 화면 간 금액 일치·기간 겹침·로그 개인정보처럼 여러 기능에 걸친 결함은 QA가 추가한 TC에서만 나옴 (TC-31 → #1, TC-32 → #2, TC-34 → #3). 단, 금액 결함(#1)은 AI TC-15도 API 응답의 totalPrice로 잡았으나, 고객이 화면마다 다른 금액을 보게 된다는 영향은 화면 간 비교 TC(TC-31)에서만 드러남
A32: 5. 명세 기반 경계값(체크인 당일, 30박, 0박)과 모호한 명세 표시(TC-02 가정)는 AI가 잘 생성함
A33: 6. AI가 명세에 없는 조건을 기대결과로 넘겨짚음: TC-04·08·09에서 'error.details에 해당 키 존재'를 기대했으나 README에는 details 포함 조건이 없음 → 자동화 실행에서 Fail로 드러나 리뷰 후 조건 제외 (AI수정 전환)
A34: v1.1
A35: 1. 처음 만든 AI TC 23건은 수정 1건, 전부 Pass. 새로 나온 문제(#7·#8·#9·#10, 머지 후 #12)는 전부 QA가 추가한 TC에서 나옴(명세 밖 상황)
A36: 2. 보강 TC에서도 결함은 QA가 추가한 관점에서 나옴(TC-73 → #14). AI 초안(Abcd1234!, "Abcd 1234")은 Pass, QA가 추가한 앞 공백 케이스(" Abcd1234")에서 #14 발견

Sheet 결함 목록
A1: 결함 ID | B1: 제목 | C1: 유형 | D1: 심각도 | E1: 관련 TC | F1: 발견 경로 | G1: 상태 | H1: 링크
A2: #1 | B2: [예약] 화면 표시 금액과 저장 금액 불일치 (저장 금액이 1박 요금만큼 많음) | C2: bug | D2: critical | E2: TC-14, TC-15, TC-31 | F2: manual | G2: Open | H2: https://github.com/sophiachae/hotel-booking-qa/issues/1
A3: #2 | B3: [예약] 체크인이 기존 예약보다 앞서면 겹치는 기간이 허용되어 중복 예약 발생 | C3: bug | D3: critical | E3: TC-32, TC-37 | F3: manual | G3: Open | H3: https://github.com/sophiachae/hotel-booking-qa/issues/2
A4: #3 | B4: [로그] 예약 API 로그에 이메일·전화번호·이름이 평문으로 기록됨 | C4: bug | D4: major | E4: TC-34, TC-60 | F4: manual | G4: Open | H4: https://github.com/sophiachae/hotel-booking-qa/issues/3
A5: #4 | B5: [예약] 이름은 영문 입력이 가능하나 전화번호는 국내 형식만 허용되어 해외 사용자 예약 불가 | C5: enhancement | D5: - | E5: TC-33 | F5: manual | G5: Open | H5: https://github.com/sophiachae/hotel-booking-qa/issues/4
A6: #5 | B6: [예약] 가운데 자리가 3자리인 전화번호(010-123-4567)가 서버 검증을 통과해 예약됨 | C6: bug | D6: minor | E6: TC-23, TC-72 | F6: automation | G6: Open | H6: https://github.com/sophiachae/hotel-booking-qa/issues/5
A7: #6 | B7: [예약] 예약 완료 후 뒤로 가기·새로고침 시 안내 없이 입력 화면이 남아 '이미 예약된 객실' 에러로 예약 실패처럼 보임 | C7: enhancement | D7: - | E7: TC-36 | F7: manual | G7: Open | H7: https://github.com/sophiachae/hotel-booking-qa/issues/6
A8: #7 | B8: [예약] 화면은 이메일을 계정 이메일로 고정하지만 서버는 다른 이메일로 회원 예약을 저장함 (UI 우회) | C8: bug | D8: major | E8: TC-65 | F8: automation | G8: Open | H8: https://github.com/sophiachae/hotel-booking-qa/issues/7
A9: #8 | B9: [예약] 예약 입력 중 세션이 만료되면 안내 없이 비회원 예약으로 저장되어 회원 예약 목록에서 사라짐 (needs-spec) | C9: bug | D9: major | E9: TC-64 | F9: automation | G9: Open | H9: https://github.com/sophiachae/hotel-booking-qa/issues/8
A10: #9 | B10: [로그인] 로그인 실패 횟수 제한이 없음 (정책 확인 필요) | C10: enhancement | D10: - | E10: TC-67 | F10: automation | G10: Open | H10: https://github.com/sophiachae/hotel-booking-qa/issues/9
A11: #10 | B11: [인증] 소셜 로그인 취소(error) 콜백에서 state를 검증하지 않음 | C11: bug | D11: minor | E11: TC-68 | F11: manual | G11: Open | H11: https://github.com/sophiachae/hotel-booking-qa/issues/10
A12: #12 | B12: [인증] 로그아웃 후 뒤로 가기 시 캐시된 회원 화면에 개인정보가 그대로 노출됨 | C12: enhancement | D12: - | E12: TC-66 | F12: manual | G12: Open | H12: https://github.com/sophiachae/hotel-booking-qa/issues/12
... A15: #15 | B15: [인증] 소셜로 가입한 계정으로 이메일 로그인하면 일반 실패 문구만 나와 로그인 방법을 알기 어려움 | C15: enhancement | D15: - | E15: TC-77 | F15: manual | G15: Open | H15: https://github.com/sophiachae/hotel-booking-qa/issues/15

Sheet 공통 표기
A1: 항목 | B1: 설명
A2: 출처 | B2: AI = AI 생성 원본 그대로 / AI수정 = QA가 절차·기대결과를 재작성 / QA추가 = AI가 누락하여 QA가 추가
A3: 실행결과 | B3: Pass / Fail / 확인필요(정책 확인 요청) / 미실행
A4: AI 원문 절차 | B4: AI수정 TC의 수정 전 절차. 리뷰 근거로 보존
A5: D | B5: AI 원문 표기. 테스트 실행일(오늘). D+n = n일 뒤 날짜
A6: 초기화 | B6: 서버 종료 → npm run reset → npm start. 샘플 데이터만 있고 예약 0건인 상태
A7: R1 | B7: AI 원문 표기. 객실 1(서울 그랜드 / 스탠다드 더블 / 120,000원), D+30~D+32, 2명으로 만든 예약
A8: 테스트 데이터 | B8: 실제 개인정보 대신 테스트용 이름·이메일·전화번호 사용
A9: 실행 환경 | B9: macOS / Chrome / localhost:3000 / 2026-10-07 ~ 10-08 (수동) 자동화: Playwright 1.64 / Chromium / localhost:3100 (전용 DB) / 2026-10-10
A10: 가정 (TC-02) | B10: minPrice는 '인원 조건을 충족하는 객실 중 최저가'로 해석. 명세에 없어 실제 동작이 다르면 판단 필요
A11: 출처 문서 | B11: README.md(미니 호텔 예약 웹앱 기능 명세)를 LLM에 입력해 TC 30건 생성 후 QA 리뷰
